Workbook

Sheet Attendance
A1: ATTENDANCE SHEET FEBRUARY 2026
A2: S.No | B2: NAME | C2: 46054 | D2: =C2+1 -> 46055 | E2: =D2+1 -> 46056 | F2: =E2+1 -> 46057 | G2: =F2+1 -> 46058 | H2: =G2+1 -> 46059 | I2: =H2+1 -> 46060 | J2: =I2+1 -> 46061 | K2: =J2+1 -> 46062 | ... AD2: =AC2+1 -> 46081 | AE2: Leave | AF2: Holiday | AG2: Present | AH2: Total | AI2: Payment
C3: =TEXT(C2,"ddd") -> Sun | D3: =TEXT(D2,"ddd") -> Mon | E3: =TEXT(E2,"ddd") -> Tue | F3: =TEXT(F2,"ddd") -> Wed | G3: =TEXT(G2,"ddd") -> Thu | H3: =TEXT(H2,"ddd") -> Fri | I3: =TEXT(I2,"ddd") -> Sat | J3: =TEXT(J2,"ddd") -> Sun | ... AD3: =TEXT(AD2,"ddd") -> Sat
A4: 1 | B4: Ahmed Azam | C4: H | D4: P | E4: L | F4: L | G4: p | H4: p | I4: p | J4: H | K4: P | L4: P | M4: L | N4: P | O4: P | P4: L | Q4: H | R4: L | S4: P | T4: L | U4: P | V4: P | W4: P | X4: H | Y4: P | Z4: P | AA4: P | AB4: P | AC4: P | AD4: P | AE4: =COUNTIF(C4:AD4,"L") -> 6 | AF4: =COUNTIF(C4:AD4,"H") -> 4 | AG4: =COUNTIF(C4:AD4,"P") -> 18 | AH4: =SUM(AF4:AG4) -> 22 | AI4: =ROUND(16500/$AH$10*AH4,0) -> 12964
A5: 2 | B5: Anand Ganesh Chopade | C5: H | D5: P | E5: P | F5: P | G5: p | H5: p | I5: p | J5: H | K5: P | L5: P | M5: P | N5: P | O5: P | P5: P | Q5: H | R5: P | S5: P | T5: P | U5: P | V5: P | W5: P | X5: H | Y5: P | Z5: P | AA5: P | AB5: P | AC5: P | AD5: P | AE5: =COUNTIF(C5:AD5,"L") -> 0 | AF5: =COUNTIF(C5:AD5,"H") -> 4 | AG5: =COUNTIF(C5:AD5,"P") -> 24 | AH5: =SUM(AF5:AG5) -> 28 | AI5: =ROUND(16500/$AH$10*AH5,0) -> 16500
A6: 3 | B6: Arundathi Jalagam | C6: H | D6: P | E6: P | F6: P | G6: p | H6: p | I6: p | J6: H | K6: P | L6: P | M6: P | N6: P | O6: P | P6: P | Q6: H | R6: L | S6: P | T6: P | U6: P | V6: P | W6: P | X6: H | Y6: P | Z6: P | AA6: P | AB6: P | AC6: P | AD6: P | AE6: =COUNTIF(C6:AD6,"L") -> 1 | AF6: =COUNTIF(C6:AD6,"H") -> 4 | AG6: =COUNTIF(C6:AD6,"P") -> 23 | AH6: =SUM(AF6:AG6) -> 27 | AI6: =ROUND(16500/$AH$10*AH6,0) -> 15911
A7: 4 | B7: Bonagiri Rehana | C7: H | D7: P | E7: P | F7: P | G7: P | H7: P | I7: P | J7: H | K7: P | L7: P | M7: P | N7: P | O7: P | P7: P | Q7: H | R7: L | S7: P | T7: P | U7: P | V7: P | W7: P | X7: H | Y7: P | Z7: P | AA7: P | AB7: P | AC7: P | AD7: P | AE7: =COUNTIF(C7:AD7,"L") -> 1 | AF7: =COUNTIF(C7:AD7,"H") -> 4 | AG7: =COUNTIF(C7:AD7,"P") -> 23 | AH7: =SUM(AF7:AG7) -> 27 | AI7: =ROUND(16500/$AH$10*AH7,0) -> 15911
A8: 5 | B8: Chouta Keerthana | C8: H | D8: P | E8: P | F8: P | G8: P | H8: P | I8: P | J8: H | K8: L | L8: P | M8: P | N8: L | O8: L | P8: L | Q8: H | R8: P | S8: P | T8: L | U8: P | V8: P | W8: P | X8: H | Y8: P | Z8: P | AA8: P | AB8: P | AC8: P | AD8: P | AE8: =COUNTIF(C8:AD8,"L") -> 5 | AF8: =COUNTIF(C8:AD8,"H") -> 4 | AG8: =COUNTIF(C8:AD8,"P") -> 19 | AH8: =SUM(AF8:AG8) -> 23 | AI8: =ROUND(16500/$AH$10*AH8,0) -> 13554
A9: 6 | B9: Deshapaga Raghavendar | C9: H | D9: L | E9: P | F9: P | G9: P | H9: L | I9: P | J9: H | K9: P | L9: P | M9: P | N9: P | O9: P | P9: P | Q9: H | R9: P | S9: P | T9: P | U9: P | V9: P | W9: P | X9: H | Y9: P | Z9: P | AA9: P | AB9: P | AC9: P | AD9: P | AE9: =COUNTIF(C9:AD9,"L") -> 2 | AF9: =COUNTIF(C9:AD9,"H") -> 4 | AG9: =COUNTIF(C9:AD9,"P") -> 22 | AH9: =SUM(AF9:AG9) -> 26 | AI9: =ROUND(16500/$AH$10*AH9,0) -> 15321
A10: 7 | B10: Dhenumakonda Lavanya | C10: H | D10: P | E10: P | F10: P | G10: P | H10: P | I10: P | J10: H | K10: P | L10: P | M10: P | N10: P | O10: P | P10: P | Q10: H | R10: P | S10: P | T10: P | U10: P | V10: P | W10: P | X10: H | Y10: P | Z10: P | AA10: P | AB10: P | AC10: P | AD10: P | AE10: =COUNTIF(C10:AD10,"L") -> 0 | AF10: =COUNTIF(C10:AD10,"H") -> 4 | AG10: =COUNTIF(C10:AD10,"P") -> 24 | AH10: =SUM(AF10:AG10) -> 28 | AI10: =ROUND(16500/$AH$10*AH10,0) -> 16500
A11: 8 | B11: Diravath Mounika | C11: H | D11: P | E11: L | F11: L | G11: L | H11: L | I11: L | J11: H | K11: P | L11: P | M11: P | N11: P | O11: P | P11: P | Q11: H | R11: P | S11: P | T11: P | U11: P | V11: P | W11: P | X11: H | Y11: P | Z11: P | AA11: P | AB11: P | AC11: P | AD11: P | AE11: =COUNTIF(C11:AD11,"L") -> 5 | AF11: =COUNTIF(C11:AD11,"H") -> 4 | AG11: =COUNTIF(C11:AD11,"P") -> 19 | AH11: =SUM(AF11:AG11) -> 23 | AI11: =ROUND(16500/$AH$10*AH11,0) -> 13554
A12: 9 | B12: Gaja Balanarayana | C12: H | D12: P | E12: P | F12: P | G12: P | H12: P | I12: P | J12: H | K12: P | L12: P | M12: P | N12: P | O12: P | P12: P | Q12: H | R12: P | S12: P | T12: P | U12: P | V12: P | W12: P | X12: H | Y12: L | Z12: L | AA12: P | AB12: P | AC12: P | AD12: P | AE12: =COUNTIF(C12:AD12,"L") -> 2 | AF12: =COUNTIF(C12:AD12,"H") -> 4 | AG12: =COUNTIF(C12:AD12,"P") -> 22 | AH12: =SUM(AF12:AG12) -> 26 | AI12: =ROUND(16500/$AH$10*AH12,0) -> 15321
A13: 10 | B13: Gopala Saritha | C13: H | D13: P | E13: P | F13: P | G13: P | H13: P | I13: P | J13: H | K13: P | L13: P | M13: P | N13: P | O13: P | P13: P | Q13: H | R13: P | S13: P | T13: P | U13: P | V13: P | W13: P | X13: H | Y13: L | Z13: L | AA13: L | AB13: P | AC13: P | AD13: P | AE13: =COUNTIF(C13:AD13,"L") -> 3 | AF13: =COUNTIF(C13:AD13,"H") -> 4 | AG13: =COUNTIF(C13:AD13,"P") -> 21 | AH13: =SUM(AF13:AG13) -> 25 | AI13: =ROUND(16500/$AH$10*AH13,0) -> 14732
A14: 11 | B14: Gudise Hemanth Kumar | C14: H | D14: P | E14: P | F14: P | G14: P | H14: P | I14: P | J14: H | K14: P | L14: P | M14: L | N14: p | O14: p | P14: P | Q14: H | R14: P | S14: L | T14: L | U14: L | V14: L | W14: L | X14: H | Y14: L | Z14: L | AA14: P | AB14: P | AC14: L | AD14: P | AE14: =COUNTIF(C14:AD14,"L") -> 9 | AF14: =COUNTIF(C14:AD14,"H") -> 4 | AG14: =COUNTIF(C14:AD14,"P") -> 15 | AH14: =SUM(AF14:AG14) -> 19 | AI14: =ROUND(16500/$AH$10*AH14,0) -> 11196
A15: 12 | B15: Jetti Hima Sindhu | C15: H | D15: P | E15: P | F15: P | G15: P | H15: P | I15: P | J15: H | K15: P | L15: P | M15: P | N15: P | O15: P | P15: P | Q15: H | R15: P | S15: P | T15: P | U15: P | V15: L | W15: P | X15: H | Y15: P | Z15: P | AA15: L | AB15: L | AC15: L | AD15: P | AE15: =COUNTIF(C15:AD15,"L") -> 4 | AF15: =COUNTIF(C15:AD15,"H") -> 4 | AG15: =COUNTIF(C15:AD15,"P") -> 20 | AH15: =SUM(AF15:AG15) -> 24 | AI15: =ROUND(16500/$AH$10*AH15,0) -> 14143
... A56: 53 | B56: Chejerla Nagavamsidhar Reddy | C56: - | D56: P | E56: P | F56: P | G56: P | H56: P | I56: P | J56: H | K56: P | L56: P | M56: P | N56: P | O56: P | P56: P | Q56: H | R56: P | S56: P | T56: P | U56: P | V56: P | W56: P | X56: H | Y56: P | Z56: P | AA56: P | AB56: P | AC56: P | AD56: P | AE56: =COUNTIF(C56:AD56,"L") -> 0 | AF56: =COUNTIF(C56:AD56,"H") -> 3 | AG56: =COUNTIF(C56:AD56,"P") -> 24 | AH56: =SUM(AF56:AG56) -> 27 | AI56: =ROUND(16500/$AH$10*AH56,0) -> 15911

Sheet Pay
D2: FEBRUARY 2026 PAYMENT
D5: S.No | E5: Name | F5: Present | G5: Pay
D6: 1 | E6: =Attendance!B4 -> Ahmed Azam | F6: =Attendance!AH4 -> 22 | G6: =ROUND(16500/$F$7*F6,0) -> 12964
D7: 2 | E7: =Attendance!B5 -> Anand Ganesh Chopade | F7: =Attendance!AH5 -> 28 | G7: =ROUND(16500/$F$7*F7,0) -> 16500
D8: 3 | E8: =Attendance!B6 -> Arundathi Jalagam | F8: =Attendance!AH6 -> 27 | G8: =ROUND(16500/$F$7*F8,0) -> 15911
D9: 4 | E9: =Attendance!B7 -> Bonagiri Rehana | F9: =Attendance!AH7 -> 27 | G9: =ROUND(16500/$F$7*F9,0) -> 15911
D10: 5 | E10: =Attendance!B8 -> Chouta Keerthana | F10: =Attendance!AH8 -> 23 | G10: =ROUND(16500/$F$7*F10,0) -> 13554
D11: 6 | E11: =Attendance!B9 -> Deshapaga Raghavendar | F11: =Attendance!AH9 -> 26 | G11: =ROUND(16500/$F$7*F11,0) -> 15321
D12: 7 | E12: =Attendance!B10 -> Dhenumakonda Lavanya | F12: =Attendance!AH10 -> 28 | G12: =ROUND(16500/$F$7*F12,0) -> 16500
D13: 8 | E13: =Attendance!B11 -> Diravath Mounika | F13: =Attendance!AH11 -> 23 | G13: =ROUND(16500/$F$7*F13,0) -> 13554
D14: 9 | E14: =Attendance!B12 -> Gaja Balanarayana | F14: =Attendance!AH12 -> 26 | G14: =ROUND(16500/$F$7*F14,0) -> 15321
D15: 10 | E15: =Attendance!B13 -> Gopala Saritha | F15: =Attendance!AH13 -> 25 | G15: =ROUND(16500/$F$7*F15,0) -> 14732
D16: 11 | E16: =Attendance!B14 -> Gudise Hemanth Kumar | F16: =Attendance!AH14 -> 19 | G16: =ROUND(16500/$F$7*F16,0) -> 11196
D17: 12 | E17: =Attendance!B15 -> Jetti Hima Sindhu | F17: =Attendance!AH15 -> 24 | G17: =ROUND(16500/$F$7*F17,0) -> 14143
... D58: 53 | E58: =Attendance!B56 -> Chejerla Nagavamsidhar Reddy | F58: =Attendance!AH56 -> 27 | G58: =ROUND(16500/$F$7*F58,0) -> 15911
E59: TOTAL | G59: =SUM(G6:G58) -> 802019

Sheet Time Sheet
A1: TIME SHEET FEBRUARY 2026 | AG1: APEL-SSA-TAR-ATA-HIRATE-MC-199 | AH1: BFHL-SSA-TAR-ATA-HIRATE-MC-210 | AI1: BWHPL-SSA-TAR-ATA-HIRATE-MC-340 | AJ1: DATL-SSA-TAR-ATA-HIRATE-MC-198 | AK1: FRHL-SSA-TAR-ATA-HIRATE-MC-197 | AL1: GAPEL-SSA-TAR-ATA-HIRATE-MC-200 | AM1: JMTL-SSA-TAR-ATA-HIRATE-MC-194 | AN1: KETL-SSA-TAR-ATA-HIRATE-MC-196 | AO1: KMTL-SSA-TAR-ATA-HIRATE-MC-195 | AP1: KTIPL-SSA-TAR-ATA-HIRATE-MC-348 | AQ1: MBEL-SSA-TAR-ATA-HIRATE-MC-192 | AR1: MHPL-SSA-TAR-ATA-HIRATE-MC-346 | AS1: MKTL-SSA-TAR-ATA-HIRATE-MC-191 | AT1: MSHPL-SSA-TAR-ATA-HIRATE-MC-343 | AU1: NAMEL-SSA-TAR-ATA-HIRATE-MC-400 | AV1: NDEPL-SSA-TAR-ATA-HIRATE-MC-190 | AW1: NKTL-SSA-TAR-ATA-HIRATE-MC-189 | AX1: SIPL-SSA-TAR-ATA-HIRATE-MC-350 | AY1: SMTL-SSA-TAR-ATA-HIRATE-MC-188 | AZ1: SPPL-SSA-TAR-ATA-HIRATE-MC-352 | BA1: WVEPL-SSA-TAR-ATA-HIRATE-MC-193 | BB1: WUPTL-SSA-TAR-ATA-HIRATE-MC-187 | BC1: FRHL-SSA-TAR-ASA-E. NSV ANALYSIS-MC-147 | BD1: LIGHTSTORM-SSA-ATMS-INST-LGS-01-MC-472 | BE1: PAY
A2: S.No | B2: NAME | C2: =Attendance!C2 -> 46054 | D2: =Attendance!D2 -> 46055 | E2: =Attendance!E2 -> 46056 | F2: =Attendance!F2 -> 46057 | G2: =Attendance!G2 -> 46058 | H2: =Attendance!H2 -> 46059 | I2: =Attendance!I2 -> 46060 | J2: =Attendance!J2 -> 46061 | ... AD2: =Attendance!AD2 -> 46081
C3: =TEXT(C2,"ddd") -> Sun | D3: =TEXT(D2,"ddd") -> Mon | E3: =TEXT(E2,"ddd") -> Tue | F3: =TEXT(F2,"ddd") -> Wed | G3: =TEXT(G2,"ddd") -> Thu | H3: =TEXT(H2,"ddd") -> Fri | I3: =TEXT(I2,"ddd") -> Sat | J3: =TEXT(J2,"ddd") -> Sun | ... AD3: =TEXT(AD2,"ddd") -> Sat
A4: 1 | B4: =Attendance!B4 -> Ahmed Azam | C4: =Attendance!C4 -> H | D4: =Attendance!D4 -> P | E4: =Attendance!E4 -> L | F4: =Attendance!F4 -> L | G4: =Attendance!G4 -> p | H4: =Attendance!H4 -> p | I4: =Attendance!I4 -> p | ... AD4: =Attendance!AD4 -> P | AE4: =Attendance!AI4/Attendance!AH4 -> 589.27273 | AF4: =(COUNTIF(C4:AD4,"P")+COUNTIF(C4:AD4,"H")) -> 22 | AG4: 0 | AH4: 0 | AI4: 0 | AJ4: =AE4*AF4 -> 12964 | AK4: 0 | AL4: 0 | AM4: 0 | AN4: 0 | AO4: 0 | AP4: 0 | AQ4: 0 | AR4: 0 | AS4: 0 | AT4: 0 | AU4: 0 | AV4: 0 | AW4: 0 | AX4: 0 | AY4: 0 | AZ4: 0 | BA4: 0 | BB4: 0 | BC4: 0 | BD4: 0 | BE4: =ROUND(SUM(AG4:BD4),0) -> 12964
A5: 2 | B5: =Attendance!B5 -> Anand Ganesh Chopade | C5: =Attendance!C5 -> H | D5: =Attendance!D5 -> P | E5: =Attendance!E5 -> P | F5: =Attendance!F5 -> P | G5: =Attendance!G5 -> p | H5: =Attendance!H5 -> p | I5: =Attendance!I5 -> p | ... AD5: =Attendance!AD5 -> P | AE5: =Attendance!AI5/Attendance!AH5 -> 589.28571 | AF5: =(COUNTIF(C5:AD5,"P")+COUNTIF(C5:AD5,"H")) -> 28 | AG5: 0 | AH5: 0 | AI5: 0 | AJ5: 0 | AK5: 0 | AL5: 0 | AM5: 0 | AN5: 0 | AO5: 0 | AP5: 0 | AQ5: 0 | AR5: 0 | AS5: 0 | AT5: 0 | AU5: 0 | AV5: 0 | AW5: 0 | AX5: 0 | AY5: 0 | AZ5: 0 | BA5: 0 | BB5: 0 | BC5: =AE5*AF5 -> 16500 | BD5: 0 | BE5: =ROUND(SUM(AG5:BD5),0) -> 16500
A6: 3 | B6: =Attendance!B6 -> Arundathi Jalagam | C6: =Attendance!C6 -> H | D6: =Attendance!D6 -> P | E6: =Attendance!E6 -> P | F6: =Attendance!F6 -> P | G6: =Attendance!G6 -> p | H6: =Attendance!H6 -> p | I6: =Attendance!I6 -> p | ... AD6: =Attendance!AD6 -> P | AE6: =Attendance!AI6/Attendance!AH6 -> 589.2963 | AF6: =(COUNTIF(C6:AD6,"P")+COUNTIF(C6:AD6,"H")) -> 27 | AG6: 0 | AH6: 0 | AI6: =AE6*13 -> 7660.8519 | AJ6: 0 | AK6: 0 | AL6: 0 | AM6: 0 | AN6: 0 | AO6: 0 | AP6: 0 | AQ6: 0 | AR6: 0 | AS6: 0 | AT6: =AE6*14 -> 8250.1481 | AU6: 0 | AV6: 0 | AW6: 0 | AX6: 0 | AY6: 0 | AZ6: 0 | BA6: 0 | BB6: 0 | BC6: 0 | BD6: 0 | BE6: =ROUND(SUM(AG6:BD6),0) -> 15911
A7: 4 | B7: =Attendance!B7 -> Bonagiri Rehana | C7: =Attendance!C7 -> H | D7: =Attendance!D7 -> P | E7: =Attendance!E7 -> P | F7: =Attendance!F7 -> P | G7: =Attendance!G7 -> P | H7: =Attendance!H7 -> P | I7: =Attendance!I7 -> P | ... AD7: =Attendance!AD7 -> P | AE7: =Attendance!AI7/Attendance!AH7 -> 589.2963 | AF7: =(COUNTIF(C7:AD7,"P")+COUNTIF(C7:AD7,"H")) -> 27 | AG7: 0 | AH7: 0 | AI7: 0 | AJ7: 0 | AK7: 0 | AL7: 0 | AM7: 0 | AN7: 0 | AO7: 0 | AP7: 0 | AQ7: 0 | AR7: 0 | AS7: 0 | AT7: 0 | AU7: =AE7*AF7 -> 15911 | AV7: 0 | AW7: 0 | AX7: 0 | AY7: 0 | AZ7: 0 | BA7: 0 | BB7: 0 | BC7: 0 | BD7: 0 | BE7: =ROUND(SUM(AG7:BD7),0) -> 15911
A8: 5 | B8: =Attendance!B8 -> Chouta Keerthana | C8: =Attendance!C8 -> H | D8: =Attendance!D8 -> P | E8: =Attendance!E8 -> P | F8: =Attendance!F8 -> P | G8: =Attendance!G8 -> P | H8: =Attendance!H8 -> P | I8: =Attendance!I8 -> P | ... AD8: =Attendance!AD8 -> P | AE8: =Attendance!AI8/Attendance!AH8 -> 589.30435 | AF8: =(COUNTIF(C8:AD8,"P")+COUNTIF(C8:AD8,"H")) -> 23 | AG8: 0 | AH8: 0 | AI8: 0 | AJ8: =AE8*AF8 -> 13554 | AK8: 0 | AL8: 0 | AM8: 0 | AN8: 0 | AO8: 0 | AP8: 0 | AQ8: 0 | AR8: 0 | AS8: 0 | AT8: 0 | AU8: 0 | AV8: 0 | AW8: 0 | AX8: 0 | AY8: 0 | AZ8: 0 | BA8: 0 | BB8: 0 | BC8: 0 | BD8: 0 | BE8: =ROUND(SUM(AG8:BD8),0) -> 13554
A9: 6 | B9: =Attendance!B9 -> Deshapaga Raghavendar | C9: =Attendance!C9 -> H | D9: =Attendance!D9 -> L | E9: =Attendance!E9 -> P | F9: =Attendance!F9 -> P | G9: =Attendance!G9 -> P | H9: =Attendance!H9 -> L | I9: =Attendance!I9 -> P | ... AD9: =Attendance!AD9 -> P | AE9: =Attendance!AI9/Attendance!AH9 -> 589.26923 | AF9: =(COUNTIF(C9:AD9,"P")+COUNTIF(C9:AD9,"H")) -> 26 | AG9: 0 | AH9: 0 | AI9: 0 | AJ9: 0 | AK9: 0 | AL9: 0 | AM9: 0 | AN9: 0 | AO9: 0 | AP9: 0 | AQ9: 0 | AR9: 0 | AS9: 0 | AT9: 0 | AU9: =AE9*AF9 -> 15321 | AV9: 0 | AW9: 0 | AX9: 0 | AY9: 0 | AZ9: 0 | BA9: 0 | BB9: 0 | BC9: 0 | BD9: 0 | BE9: =ROUND(SUM(AG9:BD9),0) -> 15321
A10: 7 | B10: =Attendance!B10 -> Dhenumakonda Lavanya | C10: =Attendance!C10 -> H | D10: =Attendance!D10 -> P | E10: =Attendance!E10 -> P | F10: =Attendance!F10 -> P | G10: =Attendance!G10 -> P | H10: =Attendance!H10 -> P | I10: =Attendance!I10 -> P | ... AD10: =Attendance!AD10 -> P | AE10: =Attendance!AI10/Attendance!AH10 -> 589.28571 | AF10: =(COUNTIF(C10:AD10,"P")+COUNTIF(C10:AD10,"H")) -> 28 | AG10: 0 | AH10: 0 | AI10: 0 | AJ10: 0 | AK10: 0 | AL10: 0 | AM10: 0 | AN10: 0 | AO10: 0 | AP10: 0 | AQ10: 0 | AR10: 0 | AS10: 0 | AT10: 0 | AU10: 0 | AV10: 0 | AW10: 0 | AX10: 0 | AY10: 0 | AZ10: 0 | BA10: 0 | BB10: 0 | BC10: =AE10*AF10 -> 16500 | BD10: 0 | BE10: =ROUND(SUM(AG10:BD10),0) -> 16500
A11: 8 | B11: =Attendance!B11 -> Diravath Mounika | C11: =Attendance!C11 -> H | D11: =Attendance!D11 -> P | E11: =Attendance!E11 -> L | F11: =Attendance!F11 -> L | G11: =Attendance!G11 -> L | H11: =Attendance!H11 -> L | I11: =Attendance!I11 -> L | ... AD11: =Attendance!AD11 -> P | AE11: =Attendance!AI11/Attendance!AH11 -> 589.30435 | AF11: =(COUNTIF(C11:AD11,"P")+COUNTIF(C11:AD11,"H")) -> 23 | AG11: 0 | AH11: 0 | AI11: 0 | AJ11: 0 | AK11: 0 | AL11: 0 | AM11: 0 | AN11: 0 | AO11: 0 | AP11: =AE11*AF11 -> 13554 | AQ11: 0 | AR11: 0 | AS11: 0 | AT11: 0 | AU11: 0 | AV11: 0 | AW11: 0 | AX11: 0 | AY11: 0 | AZ11: 0 | BA11: 0 | BB11: 0 | BC11: 0 | BD11: 0 | BE11: =ROUND(SUM(AG11:BD11),0) -> 13554
A12: 9 | B12: =Attendance!B12 -> Gaja Balanarayana | C12: =Attendance!C12 -> H | D12: =Attendance!D12 -> P | E12: =Attendance!E12 -> P | F12: =Attendance!F12 -> P | G12: =Attendance!G12 -> P | H12: =Attendance!H12 -> P | I12: =Attendance!I12 -> P | ... AD12: =Attendance!AD12 -> P | AE12: =Attendance!AI12/Attendance!AH12 -> 589.26923 | AF12: =(COUNTIF(C12:AD12,"P")+COUNTIF(C12:AD12,"H")) -> 26 | AG12: 0 | AH12: 0 | AI12: 0 | AJ12: 0 | AK12: 0 | AL12: 0 | AM12: 0 | AN12: 0 | AO12: 0 | AP12: 0 | AQ12: 0 | AR12: 0 | AS12: 0 | AT12: 0 | AU12: 0 | AV12: 0 | AW12: 0 | AX12: 0 | AY12: 0 | AZ12: 0 | BA12: 0 | BB12: 0 | BC12: =AE12*AF12 -> 15321 | BD12: 0 | BE12: =ROUND(SUM(AG12:BD12),0) -> 15321
A13: 10 | B13: =Attendance!B13 -> Gopala Saritha | C13: =Attendance!C13 -> H | D13: =Attendance!D13 -> P | E13: =Attendance!E13 -> P | F13: =Attendance!F13 -> P | G13: =Attendance!G13 -> P | H13: =Attendance!H13 -> P | I13: =Attendance!I13 -> P | ... AD13: =Attendance!AD13 -> P | AE13: =Attendance!AI13/Attendance!AH13 -> 589.28 | AF13: =(COUNTIF(C13:AD13,"P")+COUNTIF(C13:AD13,"H")) -> 25 | AG13: 0 | AH13: 0 | AI13: 0 | AJ13: 0 | AK13: =AE13*AF13 -> 14732 | AL13: 0 | AM13: 0 | AN13: 0 | AO13: 0 | AP13: 0 | AQ13: 0 | AR13: 0 | AS13: 0 | AT13: 0 | AU13: 0 | AV13: 0 | AW13: 0 | AX13: 0 | AY13: 0 | AZ13: 0 | BA13: 0 | BB13: 0 | BC13: 0 | BD13: 0 | BE13: =ROUND(SUM(AG13:BD13),0) -> 14732
A14: 11 | B14: =Attendance!B14 -> Gudise Hemanth Kumar | C14: =Attendance!C14 -> H | D14: =Attendance!D14 -> P | E14: =Attendance!E14 -> P | F14: =Attendance!F14 -> P | G14: =Attendance!G14 -> P | H14: =Attendance!H14 -> P | I14: =Attendance!I14 -> P | ... AD14: =Attendance!AD14 -> P | AE14: =Attendance!AI14/Attendance!AH14 -> 589.26316 | AF14: =(COUNTIF(C14:AD14,"P")+COUNTIF(C14:AD14,"H")) -> 19 | AG14: 0 | AH14: 0 | AI14: 0 | AJ14: 0 | AK14: 0 | AL14: 0 | AM14: 0 | AN14: 0 | AO14: 0 | AP14: 0 | AQ14: 0 | AR14: 0 | AS14: 0 | AT14: 0 | AU14: 0 | AV14: 0 | AW14: 0 | AX14: 0 | AY14: 0 | AZ14: 0 | BA14: 0 | BB14: =AE14*AF14 -> 11196 | BC14: 0 | BD14: 0 | BE14: =ROUND(SUM(AG14:BD14),0) -> 11196
A15: 12 | B15: =Attendance!B15 -> Jetti Hima Sindhu | C15: =Attendance!C15 -> H | D15: =Attendance!D15 -> P | E15: =Attendance!E15 -> P | F15: =Attendance!F15 -> P | G15: =Attendance!G15 -> P | H15: =Attendance!H15 -> P | I15: =Attendance!I15 -> P | ... AD15: =Attendance!AD15 -> P | AE15: =Attendance!AI15/Attendance!AH15 -> 589.29167 | AF15: =(COUNTIF(C15:AD15,"P")+COUNTIF(C15:AD15,"H")) -> 24 | AG15: 0 | AH15: 0 | AI15: 0 | AJ15: 0 | AK15: 0 | AL15: 0 | AM15: 0 | AN15: 0 | AO15: 0 | AP15: 0 | AQ15: 0 | AR15: =AE15*12 -> 7071.5 | AS15: 0 | AT15: 0 | AU15: 0 | AV15: 0 | AW15: 0 | AX15: 0 | AY15: 0 | AZ15: =AE15*12 -> 7071.5 | BA15: 0 | BB15: 0 | BC15: 0 | BD15: 0 | BE15: =ROUND(SUM(AG15:BD15),0) -> 14143
A16: 13 | B16: =Attendance!B16 -> K Thirupathaiah | C16: =Attendance!C16 -> H | D16: =Attendance!D16 -> P | E16: =Attendance!E16 -> P | F16: =Attendance!F16 -> P | G16: =Attendance!G16 -> P | H16: =Attendance!H16 -> P | I16: =Attendance!I16 -> P | ... AD16: =Attendance!AD16 -> P | AE16: =Attendance!AI16/Attendance!AH16 -> 589.28571 | AF16: =(COUNTIF(C16:AD16,"P")+COUNTIF(C16:AD16,"H")) -> 28 | AG16: 0 | AH16: 0 | AI16: 0 | AJ16: 0 | AK16: 0 | AL16: 0 | AM16: 0 | AN16: 0 | AO16: 0 | AP16: 0 | AQ16: 0 | AR16: 0 | AS16: 0 | AT16: 0 | AU16: 0 | AV16: 0 | AW16: 0 | AX16: 0 | AY16: 0 | AZ16: 0 | BA16: 0 | BB16: 0 | BC16: =AE16*AF16 -> 16500 | BD16: 0 | BE16: =ROUND(SUM(AG16:BD16),0) -> 16500
A17: 14 | B17: =Attendance!B17 -> Kanche Srisailam | C17: =Attendance!C17 -> H | D17: =Attendance!D17 -> P | E17: =Attendance!E17 -> P | F17: =Attendance!F17 -> P | G17: =Attendance!G17 -> P | H17: =Attendance!H17 -> P | I17: =Attendance!I17 -> P | ... AD17: =Attendance!AD17 -> P | AE17: =Attendance!AI17/Attendance!AH17 -> 589.28571 | AF17: =(COUNTIF(C17:AD17,"P")+COUNTIF(C17:AD17,"H")) -> 28 | AG17: 0 | AH17: 0 | AI17: 0 | AJ17: 0 | AK17: 0 | AL17: 0 | AM17: 0 | AN17: 0 | AO17: 0 | AP17: 0 | AQ17: 0 | AR17: 0 | AS17: 0 | AT17: 0 | AU17: 0 | AV17: 0 | AW17: 0 | AX17: 0 | AY17: 0 | AZ17: 0 | BA17: 0 | BB17: 0 | BC17: =AE17*AF17 -> 16500 | BD17: 0 | BE17: =ROUND(SUM(AG17:BD17),0) -> 16500
A18: 15 | B18: =Attendance!B18 -> Kasireddy Harish | C18: =Attendance!C18 -> H | D18: =Attendance!D18 -> P | E18: =Attendance!E18 -> P | F18: =Attendance!F18 -> P | G18: =Attendance!G18 -> P | H18: =Attendance!H18 -> P | I18: =Attendance!I18 -> P | ... AD18: =Attendance!AD18 -> P | AE18: =Attendance!AI18/Attendance!AH18 -> 589.28571 | AF18: =(COUNTIF(C18:AD18,"P")+COUNTIF(C18:AD18,"H")) -> 28 | AG18: 0 | AH18: 0 | AI18: 0 | AJ18: 0 | AK18: 0 | AL18: 0 | AM18: 0 | AN18: 0 | AO18: 0 | AP18: 0 | AQ18: 0 | AR18: 0 | AS18: 0 | AT18: 0 | AU18: 0 | AV18: 0 | AW18: 0 | AX18: 0 | AY18: 0 | AZ18: 0 | BA18: 0 | BB18: 0 | BC18: =AE18*AF18 -> 16500 | BD18: 0 | BE18: =ROUND(SUM(AG18:BD18),0) -> 16500
A19: 16 | B19: =Attendance!B19 -> Kasturi Sathish | C19: =Attendance!C19 -> H | D19: =Attendance!D19 -> P | E19: =Attendance!E19 -> P | F19: =Attendance!F19 -> P | G19: =Attendance!G19 -> P | H19: =Attendance!H19 -> P | I19: =Attendance!I19 -> P | ... AD19: =Attendance!AD19 -> P | AE19: =Attendance!AI19/Attendance!AH19 -> 589.28571 | AF19: =(COUNTIF(C19:AD19,"P")+COUNTIF(C19:AD19,"H")) -> 28 | AG19: 0 | AH19: 0 | AI19: 0 | AJ19: 0 | AK19: 0 | AL19: 0 | AM19: 0 | AN19: 0 | AO19: 0 | AP19: 0 | AQ19: 0 | AR19: 0 | AS19: 0 | AT19: 0 | AU19: 0 | AV19: 0 | AW19: 0 | AX19: 0 | AY19: 0 | AZ19: 0 | BA19: 0 | BB19: 0 | BC19: =AE19*AF19 -> 16500 | BD19: 0 | BE19: =ROUND(SUM(AG19:BD19),0) -> 16500
A20: 17 | B20: =Attendance!B20 -> Katravath Mangesh | C20: =Attendance!C20 -> H | D20: =Attendance!D20 -> P | E20: =Attendance!E20 -> P | F20: =Attendance!F20 -> P | G20: =Attendance!G20 -> P | H20: =Attendance!H20 -> P | I20: =Attendance!I20 -> P | ... AD20: =Attendance!AD20 -> P | AE20: =Attendance!AI20/Attendance!AH20 -> 589.28571 | AF20: =(COUNTIF(C20:AD20,"P")+COUNTIF(C20:AD20,"H")) -> 28 | AG20: 0 | AH20: 0 | AI20: 0 | AJ20: 0 | AK20: 0 | AL20: 0 | AM20: 0 | AN20: 0 | AO20: 0 | AP20: 0 | AQ20: 0 | AR20: 0 | AS20: 0 | AT20: 0 | AU20: 0 | AV20: 0 | AW20: 0 | AX20: 0 | AY20: 0 | AZ20: 0 | BA20: 0 | BB20: 0 | BC20: 0 | BD20: =AE20*AF20 -> 16500 | BE20: =ROUND(SUM(AG20:BD20),0) -> 16500
A21: 18 | B21: =Attendance!B21 -> Katravath Mohan Rathod | C21: =Attendance!C21 -> H | D21: =Attendance!D21 -> P | E21: =Attendance!E21 -> P | F21: =Attendance!F21 -> P | G21: =Attendance!G21 -> P | H21: =Attendance!H21 -> P | I21: =Attendance!I21 -> P | ... AD21: =Attendance!AD21 -> P | AE21: =Attendance!AI21/Attendance!AH21 -> 589.2963 | AF21: =(COUNTIF(C21:AD21,"P")+COUNTIF(C21:AD21,"H")) -> 27 | AG21: 0 | AH21: 0 | AI21: 0 | AJ21: 0 | AK21: 0 | AL21: 0 | AM21: =AE21*AF21 -> 15911 | AN21: 0 | AO21: 0 | AP21: 0 | AQ21: 0 | AR21: 0 | AS21: 0 | AT21: 0 | AU21: 0 | AV21: 0 | AW21: 0 | AX21: 0 | AY21: 0 | AZ21: 0 | BA21: 0 | BB21: 0 | BC21: 0 | BD21: 0 | BE21: =ROUND(SUM(AG21:BD21),0) -> 15911
A22: 19 | B22: =Attendance!B22 -> Katravath Radhika | C22: =Attendance!C22 -> H | D22: =Attendance!D22 -> P | E22: =Attendance!E22 -> P | F22: =Attendance!F22 -> P | G22: =Attendance!G22 -> P | H22: =Attendance!H22 -> P | I22: =Attendance!I22 -> P | ... AD22: =Attendance!AD22 -> P | AE22: =Attendance!AI22/Attendance!AH22 -> 589.30435 | AF22: =(COUNTIF(C22:AD22,"P")+COUNTIF(C22:AD22,"H")) -> 23 | AG22: 0 | AH22: 0 | AI22: 0 | AJ22: 0 | AK22: 0 | AL22: =AE22*3 -> 1767.913 | AM22: 0 | AN22: 0 | AO22: =AE22*20 -> 11786.087 | AP22: 0 | AQ22: 0 | AR22: 0 | AS22: 0 | AT22: 0 | AU22: 0 | AV22: 0 | AW22: 0 | AX22: 0 | AY22: 0 | AZ22: 0 | BA22: 0 | BB22: 0 | BC22: 0 | BD22: 0 | BE22: =ROUND(SUM(AG22:BD22),0) -> 13554
A23: 20 | B23: =Attendance!B23 -> Kodavath Swamy | C23: =Attendance!C23 -> H | D23: =Attendance!D23 -> P | E23: =Attendance!E23 -> P | F23: =Attendance!F23 -> P | G23: =Attendance!G23 -> P | H23: =Attendance!H23 -> P | I23: =Attendance!I23 -> P | ... AD23: =Attendance!AD23 -> P | AE23: =Attendance!AI23/Attendance!AH23 -> 589.28571 | AF23: =(COUNTIF(C23:AD23,"P")+COUNTIF(C23:AD23,"H")) -> 28 | AG23: 0 | AH23: 0 | AI23: 0 | AJ23: 0 | AK23: 0 | AL23: 0 | AM23: 0 | AN23: 0 | AO23: 0 | AP23: 0 | AQ23: 0 | AR23: 0 | AS23: 0 | AT23: 0 | AU23: 0 | AV23: 0 | AW23: 0 | AX23: 0 | AY23: 0 | AZ23: 0 | BA23: 0 | BB23: 0 | BC23: 0 | BD23: =AE23*AF23 -> 16500 | BE23: =ROUND(SUM(AG23:BD23),0) -> 16500
A24: 21 | B24: =Attendance!B24 -> Kolla Sudhakar | C24: =Attendance!C24 -> H | D24: =Attendance!D24 -> P | E24: =Attendance!E24 -> P | F24: =Attendance!F24 -> P | G24: =Attendance!G24 -> P | H24: =Attendance!H24 -> P | I24: =Attendance!I24 -> P | ... AD24: =Attendance!AD24 -> L | AE24: =Attendance!AI24/Attendance!AH24 -> 589.28571 | AF24: =(COUNTIF(C24:AD24,"P")+COUNTIF(C24:AD24,"H")) -> 7 | AG24: 0 | AH24: 0 | AI24: 0 | AJ24: 0 | AK24: 0 | AL24: 0 | AM24: 0 | AN24: 0 | AO24: 0 | AP24: 0 | AQ24: 0 | AR24: 0 | AS24: 0 | AT24: 0 | AU24: 0 | AV24: 0 | AW24: 0 | AX24: 0 | AY24: 0 | AZ24: 0 | BA24: 0 | BB24: 0 | BC24: =AE24*AF24 -> 4125 | BD24: 0 | BE24: =ROUND(SUM(AG24:BD24),0) -> 4125
A25: 22 | B25: =Attendance!B25 -> Kunduru Upender Reddy | C25: =Attendance!C25 -> H | D25: =Attendance!D25 -> L | E25: =Attendance!E25 -> L | F25: =Attendance!F25 -> L | G25: =Attendance!G25 -> L | H25: =Attendance!H25 -> L | I25: =Attendance!I25 -> L | ... AD25: =Attendance!AD25 -> P | AE25: =Attendance!AI25/Attendance!AH25 -> 589.28571 | AF25: =(COUNTIF(C25:AD25,"P")+COUNTIF(C25:AD25,"H")) -> 21 | AG25: 0 | AH25: 0 | AI25: 0 | AJ25: 0 | AK25: 0 | AL25: 0 | AM25: 0 | AN25: 0 | AO25: 0 | AP25: 0 | AQ25: 0 | AR25: 0 | AS25: 0 | AT25: 0 | AU25: 0 | AV25: 0 | AW25: 0 | AX25: 0 | AY25: 0 | AZ25: 0 | BA25: 0 | BB25: 0 | BC25: 0 | BD25: =AE25*AF25 -> 12375 | BE25: =ROUND(SUM(AG25:BD25),0) -> 12375
A26: 23 | B26: =Attendance!B26 -> M jathin sai | C26: =Attendance!C26 -> H | D26: =Attendance!D26 -> P | E26: =Attendance!E26 -> P | F26: =Attendance!F26 -> P | G26: =Attendance!G26 -> P | H26: =Attendance!H26 -> P | I26: =Attendance!I26 -> P | ... AD26: =Attendance!AD26 -> P | AE26: =Attendance!AI26/Attendance!AH26 -> 589.28571 | AF26: =(COUNTIF(C26:AD26,"P")+COUNTIF(C26:AD26,"H")) -> 28 | AG26: 0 | AH26: 0 | AI26: 0 | AJ26: 0 | AK26: 0 | AL26: 0 | AM26: 0 | AN26: 0 | AO26: 0 | AP26: 0 | AQ26: 0 | AR26: 0 | AS26: 0 | AT26: 0 | AU26: 0 | AV26: 0 | AW26: 0 | AX26: 0 | AY26: 0 | AZ26: 0 | BA26: 0 | BB26: 0 | BC26: 0 | BD26: =AE26*AF26 -> 16500 | BE26: =ROUND(SUM(AG26:BD26),0) -> 16500
A27: 24 | B27: =Attendance!B27 -> M Sunitha | C27: =Attendance!C27 -> H | D27: =Attendance!D27 -> P | E27: =Attendance!E27 -> P | F27: =Attendance!F27 -> P | G27: =Attendance!G27 -> P | H27: =Attendance!H27 -> P | I27: =Attendance!I27 -> P | ... AD27: =Attendance!AD27 -> P | AE27: =Attendance!AI27/Attendance!AH27 -> 589.28571 | AF27: =(COUNTIF(C27:AD27,"P")+COUNTIF(C27:AD27,"H")) -> 28 | AG27: 0 | AH27: 0 | AI27: 0 | AJ27: 0 | AK27: 0 | AL27: 0 | AM27: 0 | AN27: 0 | AO27: 0 | AP27: 0 | AQ27: 0 | AR27: 0 | AS27: 0 | AT27: 0 | AU27: 0 | AV27: 0 | AW27: 0 | AX27: 0 | AY27: 0 | AZ27: 0 | BA27: 0 | BB27: 0 | BC27: 0 | BD27: =AE27*AF27 -> 16500 | BE27: =ROUND(SUM(AG27:BD27),0) -> 16500
A28: 25 | B28: =Attendance!B28 -> M Swarupa | C28: =Attendance!C28 -> H | D28: =Attendance!D28 -> L | E28: =Attendance!E28 -> P | F28: =Attendance!F28 -> P | G28: =Attendance!G28 -> P | H28: =Attendance!H28 -> P | I28: =Attendance!I28 -> P | ... AD28: =Attendance!AD28 -> P | AE28: =Attendance!AI28/Attendance!AH28 -> 589.29167 | AF28: =(COUNTIF(C28:AD28,"P")+COUNTIF(C28:AD28,"H")) -> 24 | AG28: 0 | AH28: 0 | AI28: 0 | AJ28: 0 | AK28: 0 | AL28: 0 | AM28: 0 | AN28: 0 | AO28: 0 | AP28: 0 | AQ28: 0 | AR28: 0 | AS28: 0 | AT28: 0 | AU28: 0 | AV28: 0 | AW28: 0 | AX28: =AE28*10 -> 5892.9167 | AY28: 0 | AZ28: 0 | BA28: =AE28*14 -> 8250.0833 | BB28: 0 | BC28: 0 | BD28: 0 | BE28: =ROUND(SUM(AG28:BD28),0) -> 14143
A29: 26 | B29: =Attendance!B29 -> M.Esthar Rani | C29: =Attendance!C29 -> H | D29: =Attendance!D29 -> P | E29: =Attendance!E29 -> P | F29: =Attendance!F29 -> P | G29: =Attendance!G29 -> P | H29: =Attendance!H29 -> P | I29: =Attendance!I29 -> P | ... AD29: =Attendance!AD29 -> P | AE29: =Attendance!AI29/Attendance!AH29 -> 589.26923 | AF29: =(COUNTIF(C29:AD29,"P")+COUNTIF(C29:AD29,"H")) -> 26 | AG29: 0 | AH29: =AE29*AF29 -> 15321 | AI29: 0 | AJ29: 0 | AK29: 0 | AL29: 0 | AM29: 0 | AN29: 0 | AO29: 0 | AP29: 0 | AQ29: 0 | AR29: 0 | AS29: 0 | AT29: 0 | AU29: 0 | AV29: 0 | AW29: 0 | AX29: 0 | AY29: 0 | AZ29: 0 | BA29: 0 | BB29: 0 | BC29: 0 | BD29: 0 | BE29: =ROUND(SUM(AG29:BD29),0) -> 15321
A30: 27 | B30: =Attendance!B30 -> Mamidi Raj kumar | C30: =Attendance!C30 -> H | D30: =Attendance!D30 -> P | E30: =Attendance!E30 -> P | F30: =Attendance!F30 -> P | G30: =Attendance!G30 -> P | H30: =Attendance!H30 -> P | I30: =Attendance!I30 -> P | ... AD30: =Attendance!AD30 -> P | AE30: =Attendance!AI30/Attendance!AH30 -> 589.26923 | AF30: =(COUNTIF(C30:AD30,"P")+COUNTIF(C30:AD30,"H")) -> 26 | AG30: 0 | AH30: 0 | AI30: 0 | AJ30: 0 | AK30: 0 | AL30: 0 | AM30: 0 | AN30: 0 | AO30: 0 | AP30: 0 | AQ30: 0 | AR30: 0 | AS30: 0 | AT30: 0 | AU30: 0 | AV30: 0 | AW30: 0 | AX30: 0 | AY30: 0 | AZ30: 0 | BA30: 0 | BB30: 0 | BC30: 0 | BD30: =AE30*AF30 -> 15321 | BE30: =ROUND(SUM(AG30:BD30),0) -> 15321
A31: 28 | B31: =Attendance!B31 -> Md Mainoddin | C31: =Attendance!C31 -> H | D31: =Attendance!D31 -> P | E31: =Attendance!E31 -> P | F31: =Attendance!F31 -> P | G31: =Attendance!G31 -> P | H31: =Attendance!H31 -> P | I31: =Attendance!I31 -> P | ... AD31: =Attendance!AD31 -> P | AE31: =Attendance!AI31/Attendance!AH31 -> 589.28571 | AF31: =(COUNTIF(C31:AD31,"P")+COUNTIF(C31:AD31,"H")) -> 28 | AG31: 0 | AH31: 0 | AI31: 0 | AJ31: 0 | AK31: 0 | AL31: 0 | AM31: 0 | AN31: 0 | AO31: 0 | AP31: 0 | AQ31: 0 | AR31: 0 | AS31: 0 | AT31: 0 | AU31: 0 | AV31: 0 | AW31: 0 | AX31: 0 | AY31: 0 | AZ31: 0 | BA31: 0 | BB31: 0 | BC31: 0 | BD31: =AE31*AF31 -> 16500 | BE31: =ROUND(SUM(AG31:BD31),0) -> 16500
A32: 29 | B32: =Attendance!B32 -> Mekala Anusha | C32: =Attendance!C32 -> H | D32: =Attendance!D32 -> P | E32: =Attendance!E32 -> P | F32: =Attendance!F32 -> P | G32: =Attendance!G32 -> P | H32: =Attendance!H32 -> P | I32: =Attendance!I32 -> P | ... AD32: =Attendance!AD32 -> P | AE32: =Attendance!AI32/Attendance!AH32 -> 589.28571 | AF32: =(COUNTIF(C32:AD32,"P")+COUNTIF(C32:AD32,"H")) -> 28 | AG32: 0 | AH32: 0 | AI32: 0 | AJ32: 0 | AK32: 0 | AL32: 0 | AM32: 0 | AN32: 0 | AO32: 0 | AP32: 0 | AQ32: 0 | AR32: 0 | AS32: 0 | AT32: 0 | AU32: 0 | AV32: 0 | AW32: 0 | AX32: 0 | AY32: 0 | AZ32: 0 | BA32: 0 | BB32: 0 | BC32: 0 | BD32: =AE32*AF32 -> 16500 | BE32: =ROUND(SUM(AG32:BD32),0) -> 16500
A33: 30 | B33: =Attendance!B33 -> Mohammad Naziya | C33: =Attendance!C33 -> H | D33: =Attendance!D33 -> P | E33: =Attendance!E33 -> P | F33: =Attendance!F33 -> P | G33: =Attendance!G33 -> P | H33: =Attendance!H33 -> P | I33: =Attendance!I33 -> P | ... AD33: =Attendance!AD33 -> P | AE33: =Attendance!AI33/Attendance!AH33 -> 589.28571 | AF33: =(COUNTIF(C33:AD33,"P")+COUNTIF(C33:AD33,"H")) -> 28 | AG33: 0 | AH33: 0 | AI33: 0 | AJ33: 0 | AK33: 0 | AL33: 0 | AM33: 0 | AN33: 0 | AO33: 0 | AP33: 0 | AQ33: 0 | AR33: 0 | AS33: 0 | AT33: 0 | AU33: 0 | AV33: 0 | AW33: 0 | AX33: 0 | AY33: 0 | AZ33: 0 | BA33: 0 | BB33: 0 | BC33: 0 | BD33: =AE33*AF33 -> 16500 | BE33: =ROUND(SUM(AG33:BD33),0) -> 16500
A34: 31 | B34: =Attendance!B34 -> Mohammad Shaheen Begum | C34: =Attendance!C34 -> H | D34: =Attendance!D34 -> P | E34: =Attendance!E34 -> P | F34: =Attendance!F34 -> P | G34: =Attendance!G34 -> P | H34: =Attendance!H34 -> P | I34: =Attendance!I34 -> P | ... AD34: =Attendance!AD34 -> P | AE34: =Attendance!AI34/Attendance!AH34 -> 589.27273 | AF34: =(COUNTIF(C34:AD34,"P")+COUNTIF(C34:AD34,"H")) -> 22 | AG34: 0 | AH34: 0 | AI34: 0 | AJ34: =AE34*AF34 -> 12964 | AK34: 0 | AL34: 0 | AM34: 0 | AN34: 0 | AO34: 0 | AP34: 0 | AQ34: 0 | AR34: 0 | AS34: 0 | AT34: 0 | AU34: 0 | AV34: 0 | AW34: 0 | AX34: 0 | AY34: 0 | AZ34: 0 | BA34: 0 | BB34: 0 | BC34: 0 | BD34: 0 | BE34: =ROUND(SUM(AG34:BD34),0) -> 12964
A35: 32 | B35: =Attendance!B35 -> Mohammed Yaqoob khan | C35: =Attendance!C35 -> H | D35: =Attendance!D35 -> P | E35: =Attendance!E35 -> P | F35: =Attendance!F35 -> P | G35: =Attendance!G35 -> P | H35: =Attendance!H35 -> L | I35: =Attendance!I35 -> L | ... AD35: =Attendance!AD35 -> P | AE35: =Attendance!AI35/Attendance!AH35 -> 589.28 | AF35: =(COUNTIF(C35:AD35,"P")+COUNTIF(C35:AD35,"H")) -> 25 | AG35: 0 | AH35: 0 | AI35: 0 | AJ35: 0 | AK35: 0 | AL35: 0 | AM35: 0 | AN35: 0 | AO35: 0 | AP35: 0 | AQ35: 0 | AR35: 0 | AS35: 0 | AT35: 0 | AU35: 0 | AV35: 0 | AW35: 0 | AX35: 0 | AY35: 0 | AZ35: 0 | BA35: 0 | BB35: 0 | BC35: 0 | BD35: =AE35*AF35 -> 14732 | BE35: =ROUND(SUM(AG35:BD35),0) -> 14732
A36: 33 | B36: =Attendance!B36 -> Mudavath Balakoti | C36: =Attendance!C36 -> H | D36: =Attendance!D36 -> P | E36: =Attendance!E36 -> P | F36: =Attendance!F36 -> P | G36: =Attendance!G36 -> P | H36: =Attendance!H36 -> P | I36: =Attendance!I36 -> P | ... AD36: =Attendance!AD36 -> P | AE36: =Attendance!AI36/Attendance!AH36 -> 589.29167 | AF36: =(COUNTIF(C36:AD36,"P")+COUNTIF(C36:AD36,"H")) -> 24 | AG36: 0 | AH36: 0 | AI36: 0 | AJ36: 0 | AK36: 0 | AL36: 0 | AM36: 0 | AN36: 0 | AO36: 0 | AP36: 0 | AQ36: 0 | AR36: 0 | AS36: 0 | AT36: 0 | AU36: 0 | AV36: 0 | AW36: 0 | AX36: 0 | AY36: 0 | AZ36: 0 | BA36: 0 | BB36: 0 | BC36: 0 | BD36: =AE36*AF36 -> 14143 | BE36: =ROUND(SUM(AG36:BD36),0) -> 14143
A37: 34 | B37: =Attendance!B37 -> Mudavath Kiran | C37: =Attendance!C37 -> H | D37: =Attendance!D37 -> P | E37: =Attendance!E37 -> P | F37: =Attendance!F37 -> P | G37: =Attendance!G37 -> P | H37: =Attendance!H37 -> P | I37: =Attendance!I37 -> P | ... AD37: =Attendance!AD37 -> P | AE37: =Attendance!AI37/Attendance!AH37 -> 589.2963 | AF37: =(COUNTIF(C37:AD37,"P")+COUNTIF(C37:AD37,"H")) -> 27 | AG37: 0 | AH37: 0 | AI37: 0 | AJ37: 0 | AK37: 0 | AL37: 0 | AM37: 0 | AN37: 0 | AO37: 0 | AP37: 0 | AQ37: =AE37*14 -> 8250.1481 | AR37: 0 | AS37: =AE37*13 -> 7660.8519 | AT37: 0 | AU37: 0 | AV37: 0 | AW37: 0 | AX37: 0 | AY37: 0 | AZ37: 0 | BA37: 0 | BB37: 0 | BC37: 0 | BD37: 0 | BE37: =ROUND(SUM(AG37:BD37),0) -> 15911
A38: 35 | B38: =Attendance!B38 -> Mudavath Ramesh | C38: =Attendance!C38 -> H | D38: =Attendance!D38 -> P | E38: =Attendance!E38 -> P | F38: =Attendance!F38 -> P | G38: =Attendance!G38 -> P | H38: =Attendance!H38 -> P | I38: =Attendance!I38 -> P | ... AD38: =Attendance!AD38 -> P | AE38: =Attendance!AI38/Attendance!AH38 -> 589.28 | AF38: =(COUNTIF(C38:AD38,"P")+COUNTIF(C38:AD38,"H")) -> 25 | AG38: 0 | AH38: 0 | AI38: 0 | AJ38: 0 | AK38: 0 | AL38: 0 | AM38: 0 | AN38: 0 | AO38: 0 | AP38: 0 | AQ38: 0 | AR38: 0 | AS38: 0 | AT38: 0 | AU38: 0 | AV38: 0 | AW38: 0 | AX38: 0 | AY38: 0 | AZ38: 0 | BA38: 0 | BB38: 0 | BC38: 0 | BD38: =AE38*AF38 -> 14732 | BE38: =ROUND(SUM(AG38:BD38),0) -> 14732
A39: 36 | B39: =Attendance!B39 -> Neeli Srivani | C39: =Attendance!C39 -> H | D39: =Attendance!D39 -> P | E39: =Attendance!E39 -> P | F39: =Attendance!F39 -> P | G39: =Attendance!G39 -> P | H39: =Attendance!H39 -> P | I39: =Attendance!I39 -> P | ... AD39: =Attendance!AD39 -> P | AE39: =Attendance!AI39/Attendance!AH39 -> 589.26923 | AF39: =(COUNTIF(C39:AD39,"P")+COUNTIF(C39:AD39,"H")) -> 26 | AG39: 0 | AH39: 0 | AI39: 0 | AJ39: 0 | AK39: 0 | AL39: 0 | AM39: 0 | AN39: 0 | AO39: 0 | AP39: 0 | AQ39: 0 | AR39: 0 | AS39: 0 | AT39: 0 | AU39: 0 | AV39: 0 | AW39: 0 | AX39: 0 | AY39: 0 | AZ39: 0 | BA39: 0 | BB39: 0 | BC39: 0 | BD39: =AE39*AF39 -> 15321 | BE39: =ROUND(SUM(AG39:BD39),0) -> 15321
A40: 37 | B40: =Attendance!B40 -> Padira Radhika | C40: =Attendance!C40 -> H | D40: =Attendance!D40 -> P | E40: =Attendance!E40 -> P | F40: =Attendance!F40 -> P | G40: =Attendance!G40 -> P | H40: =Attendance!H40 -> P | I40: =Attendance!I40 -> P | ... AD40: =Attendance!AD40 -> P | AE40: =Attendance!AI40/Attendance!AH40 -> 589.28571 | AF40: =(COUNTIF(C40:AD40,"P")+COUNTIF(C40:AD40,"H")) -> 28 | AG40: 0 | AH40: 0 | AI40: 0 | AJ40: 0 | AK40: 0 | AL40: 0 | AM40: 0 | AN40: 0 | AO40: 0 | AP40: 0 | AQ40: 0 | AR40: 0 | AS40: 0 | AT40: 0 | AU40: 0 | AV40: 0 | AW40: 0 | AX40: 0 | AY40: 0 | AZ40: 0 | BA40: 0 | BB40: 0 | BC40: 0 | BD40: =AE40*AF40 -> 16500 | BE40: =ROUND(SUM(AG40:BD40),0) -> 16500
...

Sheet Sheet2
A1: Total Hrs - February 2025 | F1: 8
A2: Project | B2: HiRATE | C2: E-Nexco | D2: TRaNAC | E2: Lightstorm
A3: GAEPL | B3: 347 | E3: 5000 | F3: =ROUND(B3/$F$1,0) -> 43 | H3: =ROUND(E3/F1,0) -> 625 | L3: HiRATE | N3: HiRATE | P3: E-Nexco | R3: Lightstorm
A4: KMTPL | B4: 159 | F4: =ROUND(B4/$F$1,0) -> 20 | J4: Ahmed Azam | K4: 22 | L4: DATL | M4: 22
A5: FRHL | B5: 199 | C5: 1595 | F5: =ROUND(B5/$F$1,0) -> 25 | G5: =ROUND(C5/F1,0) -> 199 | J5: Anand Ganesh Chopade | K5: 28 | P5: FRHL | Q5: 28
A6: MHPL | B6: 97 | F6: =ROUND(B6/$F$1,0) -> 12 | J6: Arundathi Jalagam | K6: 27 | L6: MSHP | M6: 14 | N6: BWHPL | O6: 13
A7: SPPL | B7: 94 | F7: =ROUND(B7/$F$1,0) -> 12 | J7: Bonagiri Rehana | K7: 27 | L7: NAM | M7: 27
A8: MSHP | B8: 112 | F8: =ROUND(B8/$F$1,0) -> 14 | J8: Chouta Keerthana | K8: 23 | L8: DATL | M8: 23
A9: BWHPL | B9: 104 | F9: =ROUND(B9/$F$1,0) -> 13 | J9: Deshapaga Raghavendar | K9: 26 | L9: NAM | M9: 26
A10: APEL | B10: 150 | F10: =ROUND(B10/$F$1,0) -> 19 | J10: Dhenumakonda Lavanya | K10: 28 | P10: FRHL | Q10: 28
A11: KTIPL | B11: 183 | F11: =ROUND(B11/$F$1,0) -> 23 | J11: Diravath Mounika | K11: 23 | L11: KTIPL | M11: 23
A12: NDEPL | B12: 164 | F12: =ROUND(B12/$F$1,0) -> 21 | J12: Gaja Balanarayana | K12: 26 | P12: FRHL | Q12: 26
A13: SIPL | B13: 77 | F13: =ROUND(B13/$F$1,0) -> 10 | J13: Gopala Saritha | K13: 25 | L13: FRHL | M13: 25
A14: WVEL | B14: 108 | F14: =ROUND(B14/$F$1,0) -> 14 | J14: Gudise Hemanth Kumar | K14: 19 | L14: WUPTL | M14: 19
A15: MKTL | B15: 105 | F15: =ROUND(B15/$F$1,0) -> 13 | J15: Jetti Hima Sindhu | K15: 24 | L15: MHPL | M15: 12 | N15: SPPL | O15: 12
A16: KETPL | B16: 128 | F16: =ROUND(B16/$F$1,0) -> 16 | J16: K Thirupathaiah | K16: 28 | P16: FRHL | Q16: 28
A17: SMTPL | B17: 127 | F17: =ROUND(B17/$F$1,0) -> 16 | J17: Kanche Srisailam | K17: 28 | P17: FRHL | Q17: 28
A18: NKTPL | B18: 126 | F18: =ROUND(B18/$F$1,0) -> 16 | J18: Kasireddy Harish | K18: 28 | P18: FRHL | Q18: 28
A19: JMTPL | B19: 219 | F19: =ROUND(B19/$F$1,0) -> 27 | J19: Kasturi Sathish | K19: 28 | P19: FRHL | Q19: 28
A20: DATL | B20: 539 | F20: =ROUND(B20/$F$1,0) -> 67 | J20: Katravath Mangesh | K20: 28 | R20: Lightstorm | S20: 28
A21: BFHL | B21: 207 | F21: =ROUND(B21/$F$1,0) -> 26 | J21: Katravath Mohan Rathod | K21: 27 | L21: JMTPL | M21: 27
A22: NAM | B22: 425 | F22: =ROUND(B22/$F$1,0) -> 53 | J22: Katravath Radhika | K22: 23 | L22: KMTPL | M22: 20 | N22: GAEPL | O22: 3
A23: MBEL | B23: 115 | F23: =ROUND(B23/$F$1,0) -> 14 | J23: Kodavath Swamy | K23: 28 | R23: Lightstorm | S23: 28
A24: WUPTL | B24: 154 | F24: =ROUND(B24/$F$1,0) -> 19 | J24: Kolla Sudhakar | K24: 7 | P24: FRHL | Q24: 7
A25: Total Hrs - JUNE 2024 | B25: 3939 | C25: 1595 | D25: 0 | E25: 5000 | J25: Kunduru Upender Reddy | K25: 21 | R25: Lightstorm | S25: 21
A26: 10534 | J26: M jathin sai | K26: 28 | R26: Lightstorm | S26: 28
J27: M Sunitha | K27: 28 | R27: Lightstorm | S27: 28
A28: CVI-TRAI-T&T-M&A_TDD-TOT-1-MC-485 | J28: M Swarupa | K28: 24 | L28: SIPL | M28: 10 | N28: WVEL | O28: 14
A29: TOT-1 Tranac WBS | J29: M.Esthar Rani | K29: 26 | L29: BFHL | M29: 26
J30: Mamidi Raj kumar | K30: 26 | R30: Lightstorm | S30: 26
J31: Md Mainoddin | K31: 28 | R31: Lightstorm | S31: 28
J32: Mekala Anusha | K32: 28 | R32: Lightstorm | S32: 28
J33: Mohammad Naziya | K33: 28 | R33: Lightstorm | S33: 28
J34: Mohammad Shaheen Begum | K34: 22 | L34: DATL | M34: 22
J35: Mohammed Yaqoob khan | K35: 25 | R35: Lightstorm | S35: 25
J36: Mudavath Balakoti | K36: 24 | R36: Lightstorm | S36: 24
J37: Mudavath Kiran | K37: 27 | L37: MKTL | M37: 13 | N37: MBEL | O37: 14
J38: Mudavath Ramesh | K38: 25 | R38: Lightstorm | S38: 25
J39: Neeli Srivani | K39: 26 | R39: Lightstorm | S39: 26
J40: Padira Radhika | K40: 28 | R40: Lightstorm | S40: 28
...

Sheet Sheet1
A1: Total Hrs - December 2025 | F1: 8
A2: Project | B2: HiRATE | C2: E-Nexco | D2: TRaNAC | E2: Lightstorm | F2: 1500/OT1/AT/LSTR/001/001 | J2: HiRATE | N2: E-Nexco | P2: Lightstorm
A3: GAEPL | B3: 347 | E3: 4280 | F3: =ROUND(B3/$F$1,0) -> 43 | G3: =ROUND(E3/F1,0) -> 535 | H3: Ahmed Azam | I3: 29 | N3: KTIPL | O3: 29
A4: KMTPL | B4: 159 | F4: =ROUND(B4/$F$1,0) -> 20 | H4: Anand Ganesh Chopade | I4: 30 | N4: KTIPL | O4: 30
A5: FRHL | B5: 199 | F5: =ROUND(B5/$F$1,0) -> 25 | H5: Arundathi Jalagam | I5: 28 | N5: KTIPL | O5: 28
A6: MHPL | B6: 97 | F6: =ROUND(B6/$F$1,0) -> 12 | H6: Bollapelly Sowmya | I6: 23 | J6: KTIPL | K6: 23
A7: SPPL | B7: 94 | F7: =ROUND(B7/$F$1,0) -> 12 | H7: Bonagiri Rehana | I7: 31 | J7: NDEPL | K7: 21 | L7: SIPL | M7: 10
A8: MSHP | B8: 112 | F8: =ROUND(B8/$F$1,0) -> 14 | H8: Chouta Keerthana | I8: 28 | N8: KTIPL | O8: 28
A9: BWHPL | B9: 104 | F9: =ROUND(B9/$F$1,0) -> 13 | H9: Deshapaga Raghavendar | I9: 28 | N9: KTIPL | O9: 28
A10: APEL | B10: 150 | F10: =ROUND(B10/$F$1,0) -> 19 | H10: Dhenumakonda Lavanya | I10: 31 | N10: KTIPL | O10: 31
A11: KTIPL | B11: 183 | C11: 1464 | F11: =ROUND(B11/$F$1,0) -> 23 | G11: =ROUND(C11/$F$1,0) -> 183 | H11: Diravath Mounika | I11: 22 | J11: GAEPL | K11: 22
A12: NDEPL | B12: 164 | C12: 1309 | F12: =ROUND(B12/$F$1,0) -> 21 | G12: =ROUND(C12/$F$1,0) -> 164 | H12: Gaja Balanarayana | I12: 30 | N12: NDEPL | O12: 30
A13: SIPL | B13: 77 | F13: =ROUND(B13/$F$1,0) -> 10 | H13: Gopala Saritha | I13: 28 | N13: NDEPL | O13: 28
A14: WVEL | B14: 108 | F14: =ROUND(B14/$F$1,0) -> 14 | H14: Gudise Hemanth Kumar | I14: 29 | N14: NDEPL | O14: 29
A15: MKTL | B15: 105 | F15: =ROUND(B15/$F$1,0) -> 13 | H15: Jetti Hima Sindhu | I15: 30 | J15: SMTPL | K15: 16 | L15: MBEL | M15: 14
A16: KETPL | B16: 128 | F16: =ROUND(B16/$F$1,0) -> 16 | H16: K Thirupathaiah | I16: 27 | J16: JMTPL | K16: 27
A17: SMTPL | B17: 127 | F17: =ROUND(B17/$F$1,0) -> 16 | H17: Kanche Srisailam | I17: 26 | J17: BFHL | K17: 26
A18: NKTPL | B18: 126 | F18: =ROUND(B18/$F$1,0) -> 16 | H18: Kasireddy Harish | I18: 31 | N18: NDEPL | O18: 31
A19: JMTPL | B19: 219 | F19: =ROUND(B19/$F$1,0) -> 27 | H19: Katravath Mangesh | I19: 28 | N19: NDEPL | O19: 28
A20: DATL | B20: 539 | F20: =ROUND(B20/$F$1,0) -> 67 | H20: Katravath Mohan Rathod | I20: 27 | J20: MSHP | K20: 14 | L20: BWHPL | M20: 13
A21: BFHL | B21: 207 | F21: =ROUND(B21/$F$1,0) -> 26 | H21: Katravath Radhika | I21: 28 | P21: GAEPL | Q21: 28 | R21: 1500/OT1/AT/LSTR/001/001
A22: NAM | B22: 425 | F22: =ROUND(B22/$F$1,0) -> 53 | H22: Kodavath Swamy | I22: 31 | P22: GAEPL | Q22: 31
A23: MBEL | B23: 115 | F23: =ROUND(B23/$F$1,0) -> 14 | H23: Kolla Sudhakar | I23: 28 | P23: GAEPL | Q23: 28
A24: WUPTL | B24: 154 | F24: =ROUND(B24/$F$1,0) -> 19 | H24: Kunduru Upender Reddy | I24: 28 | P24: GAEPL | Q24: 28
A25: Total Hrs - JUNE 2024 | B25: 3939 | C25: 2773 | D25: 0 | E25: 4280 | H25: M jathin sai | I25: 31 | P25: GAEPL | Q25: 31
A26: 10992 | H26: M Sunitha | I26: 30 | P26: GAEPL | Q26: 30
H27: M Swarupa | I27: 28 | P27: GAEPL | Q27: 28
H28: M.Esther Rani | I28: 28 | P28: GAEPL | Q28: 28
H29: Mamidi Raj kumar | I29: 25 | J29: FRHL | K29: 25
H30: Md Mainoddin | I30: 28 | P30: GAEPL | Q30: 28
H31: Mekala Anusha | I31: 30 | P31: GAEPL | Q31: 30
H32: Mohammad Naziya | I32: 30 | P32: GAEPL | Q32: 30
H33: Mohammad Shaheen Begum | I33: 29 | P33: GAEPL | Q33: 29
H34: Mohammed Yaqoob khan | I34: 30 | P34: GAEPL | Q34: 30
H35: Mudavath Balakoti | I35: 30 | P35: GAEPL | Q35: 30
H36: Mudavath Kiran | I36: 19 | J36: WUPTL | K36: 19
H37: Mudavath Ramesh | I37: 27 | J37: WVEL | K37: 14 | L37: MKTL | M37: 13
H38: Neeli Srivani | I38: 29 | P38: GAEPL | Q38: 29
H39: Pandiri Punith kumar | I39: 16 | J39: NKTPL | K39: 16
H40: Poojari Ramu | I40: 20 | J40: KMTPL | K40: 20
...
